Workbook

Sheet Definitions
B2: Definition scénario/phase
B3: No | G3: Probabilité
B4: 1a-0 | C4: rien | G4: =[1]Aperçu_phases!$N$3 -> 0.71288848 | I4: c'est 1- la probabilité de recouper des conduits
B5: 1a-1 | C5: 1a.1 | G5: =[1]Aperçu_phases!$N$4 -> 0.15133278
B6: 1a-2 | C6: 1a.1 | D6: 1a.2 | G6: =[1]Aperçu_phases!$N$4*[1]Aperçu_phases!$N$5 -> 0.022901611
B7: 1a-3 | C7: 1a.1 | D7: 1a.2 | E7: 1a.3 | G7: =[1]Aperçu_phases!$N$4*[1]Aperçu_phases!$N$5*[1]Aperçu_phases!$N$6 -> 0.00023363338
B8: 1a-4 | C8: 1a.2 | G8: =[1]Aperçu_phases!$N$5 -> 0.15133278
B9: 1a-5 | C9: 1a.2 | D9: 1a.3 | G9: =[1]Aperçu_phases!$N$5*[1]Aperçu_phases!$N$6 -> 0.0015438385
B10: 1a-6 | C10: 1a.3 | G10: =[1]Aperçu_phases!$N$6 -> 0.010201613
B12: Definition scénario/phase
B13: No | G13: Probabilité
B14: 1b-0 | C14: rien | G14: =[1]Aperçu_phases!$N$9 -> 0.69862223 | I14: c'est 1- la probabilité de recouper des conduits
B15: 1b-1 | C15: 1b.1 | G15: =[1]Aperçu_phases!$N$10 -> 0.14734469
B16: 1b-2 | C16: 1b.1 | D16: 1b.2 | G16: =[1]Aperçu_phases!$N$10*[1]Aperçu_phases!$N$11 -> 0.021710458
B17: 1b-3 | C17: 1b.1 | D17: 1b.2 | E17: 1b.3 | G17: =[1]Aperçu_phases!$N$10*[1]Aperçu_phases!$N$11*[1]Aperçu_phases!$N$12 -> 0.00084805222
B18: 1b-4 | C18: 1b.2 | G18: =[1]Aperçu_phases!$N$11 -> 0.14734469
B19: 1b-5 | C19: 1b.2 | D19: 1b.3 | G19: =[1]Aperçu_phases!$N$11*[1]Aperçu_phases!$N$12 -> 0.0057555668
B20: 1b-6 | C20: 1b.3 | G20: =[1]Aperçu_phases!$N$12 -> 0.039061921
B22: Definition scénario/phase
B23: No | G23: Probabilité
B24: 2a-0 | C24: rien | G24: =[1]Aperçu_phases!$N$15 -> 0.97454727 | I24: c'est 1- la probabilité de recouper des conduits
B25: 2a-1 | C25: 2a.1 | G25: =[1]Aperçu_phases!$N$16 -> 0.0085572621
B26: 2a-2 | C26: 2a.1 | D26: 2a.2 | G26: =[1]Aperçu_phases!$N$16*[1]Aperçu_phases!$N$17 -> 7.3226735e-05
B27: 2a-3 | C27: 2a.1 | D27: 2a.2 | E27: 2a.3 | G27: =[1]Aperçu_phases!$N$16*[1]Aperçu_phases!$N$17*[1]Aperçu_phases!$N$18 -> 6.2662037e-07
B28: 2a-4 | C28: 2a.1 | D28: 2a.2 | E28: 2a.3 | F28: 2a.4 | G28: =[1]Aperçu_phases!$N$16*[1]Aperçu_phases!$N$17*[1]Aperçu_phases!$N$18*[1]Aperçu_phases!$N$19 -> 5.3621547e-09
B29: 2a-5 | C29: 2a.2 | G29: =[1]Aperçu_phases!$N$17 -> 0.0085572621
B30: 2a-6 | C30: 2a.2 | D30: 2a.3 | G30: =[1]Aperçu_phases!$N$17*[1]Aperçu_phases!$N$18 -> 7.3226735e-05
B31: 2a-7 | C31: 2a.2 | D31: 2a.3 | E31: 2a.4 | G31: =[1]Aperçu_phases!$N$17*[1]Aperçu_phases!$N$18*[1]Aperçu_phases!$N$19 -> 6.2662037e-07
B32: 2a-8 | C32: 2a.3 | G32: =[1]Aperçu_phases!$N$18 -> 0.0085572621
B33: 2a-9 | C33: 2a.3 | D33: 2a.4 | G33: =[1]Aperçu_phases!$N$18*[1]Aperçu_phases!$N$19 -> 7.3226735e-05
B34: 2a-10 | C34: 2a.4 | G34: =[1]Aperçu_phases!$N$19 -> 0.0085572621

Sheet simul_1a_1b_2a
F1: En principe, il suffit de stocker les définition et de faire tourner des boucles dans le code.
A2: Simulations à affectuer | F2: La probabilité de non recoupement ne doit pas être écrite dans le tableau, mais calculée à partir des probabilités de recoupement (1- prob recoup)
J3: Qsim (T5) (aléatoire pour l'essai)
F4: Prob. 1a | G4: Prob. 1b | H4: Prob. 2a | I4: Probabilité combinée | J4: Portail Est | K4: Danger | L4: Fenster | M4: Entw.
A5: Phase 1a | B5: 1a-0 | F5: =Definitions!G4 -> 0.71288848 | I5: =SUM(F5+G5+H5) -> 0.71288848 | J5: =_xlfn.NORM.INV(RAND(),4,2) -> 2.7510915 | K5: =I5*J5 -> 1.9612214
B6: 1a-1 | F6: =Definitions!G5 -> 0.15133278 | I6: =SUM(F6+G6+H6) -> 0.15133278 | J6: =_xlfn.NORM.INV(RAND(),4,2) -> 2.8181114 | K6: =I6*J6 -> 0.42647265
B7: 1a-2 | F7: =Definitions!G6 -> 0.022901611 | I7: =SUM(F7+G7+H7) -> 0.022901611 | J7: =_xlfn.NORM.INV(RAND(),4,2) -> 5.5901136 | K7: =I7*J7 -> 0.12802261
B8: 1a-3 | F8: =Definitions!G7 -> 0.00023363338 | I8: =SUM(F8+G8+H8) -> 0.00023363338 | J8: =_xlfn.NORM.INV(RAND(),4,2) -> 3.3174557 | K8: =I8*J8 -> 0.0007750684
B9: 1a-4 | F9: =Definitions!G8 -> 0.15133278 | I9: =SUM(F9+G9+H9) -> 0.15133278 | J9: =_xlfn.NORM.INV(RAND(),4,2) -> 2.8416097 | K9: =I9*J9 -> 0.4300287
B10: 1a-5 | F10: =Definitions!G9 -> 0.0015438385 | I10: =SUM(F10+G10+H10) -> 0.0015438385 | J10: =_xlfn.NORM.INV(RAND(),4,2) -> 2.8392624 | K10: =I10*J10 -> 0.0043833626
B11: 1a-6 | F11: =Definitions!G10 -> 0.010201613 | I11: =SUM(F11+G11+H11) -> 0.010201613 | J11: =_xlfn.NORM.INV(RAND(),4,2) -> 4.5472923 | K11: =I11*J11 -> 0.046389717
A12: Phase 1b | B12: 1a-0 | C12: 1b-0 | I12: =IF(1-(SUM(I13:I18))<0,0,1-(SUM(I13:I18))) -> 0.63793462 | J12: =_xlfn.NORM.INV(RAND(),4,2) -> 1.6595485 | K12: =I12*J12 -> 1.0586834
C13: 1b-1 | G13: =Definitions!G$15 -> 0.14734469 | I13: =SUM(F13+G13+H13) -> 0.14734469 | J13: =_xlfn.NORM.INV(RAND(),4,2) -> 2.9944641 | K13: =I13*J13 -> 0.4412184
C14: 1b-2 | G14: =Definitions!G$16 -> 0.021710458 | I14: =SUM(F14+G14+H14) -> 0.021710458 | J14: =_xlfn.NORM.INV(RAND(),4,2) -> 1.9299665 | K14: =I14*J14 -> 0.041900458
C15: 1b-3 | G15: =Definitions!G$17 -> 0.00084805222 | I15: =SUM(F15+G15+H15) -> 0.00084805222 | J15: =_xlfn.NORM.INV(RAND(),4,2) -> 3.8339147 | K15: =I15*J15 -> 0.0032513599
C16: 1b-4 | G16: =Definitions!G$18 -> 0.14734469 | I16: =SUM(F16+G16+H16) -> 0.14734469 | J16: =_xlfn.NORM.INV(RAND(),4,2) -> 5.9511829 | K16: =I16*J16 -> 0.87687522
C17: 1b-5 | G17: =Definitions!G$19 -> 0.0057555668 | I17: =SUM(F17+G17+H17) -> 0.0057555668 | J17: =_xlfn.NORM.INV(RAND(),4,2) -> 3.3756756 | K17: =I17*J17 -> 0.019428926
C18: 1b-6 | G18: =Definitions!G$20 -> 0.039061921 | I18: =SUM(F18+G18+H18) -> 0.039061921 | J18: =_xlfn.NORM.INV(RAND(),4,2) -> 6.5743212 | K18: =I18*J18 -> 0.25680562
B19: 1a-1 | C19: 1b-0 | F19: =F$6 -> 0.15133278 | I19: =IF(1-(SUM(I20:I25))<0,0,1-(SUM(I20:I25))) -> 0 | J19: =_xlfn.NORM.INV(RAND(),4,2) -> 3.0885415 | K19: =I19*J19 -> 0
C20: 1b-1 | F20: =F$6 -> 0.15133278 | G20: =Definitions!G$15 -> 0.14734469 | I20: =SUM(F20+G20+H20) -> 0.29867748 | J20: =_xlfn.NORM.INV(RAND(),4,2) -> 4.0363328 | K20: =I20*J20 -> 1.2055617
C21: 1b-2 | F21: =F$6 -> 0.15133278 | G21: =Definitions!G$16 -> 0.021710458 | I21: =SUM(F21+G21+H21) -> 0.17304324 | J21: =_xlfn.NORM.INV(RAND(),4,2) -> 1.0598049 | K21: =I21*J21 -> 0.18339208
C22: 1b-3 | F22: =F$6 -> 0.15133278 | G22: =Definitions!G$17 -> 0.00084805222 | I22: =SUM(F22+G22+H22) -> 0.15218084 | J22: =_xlfn.NORM.INV(RAND(),4,2) -> 8.1952348 | K22: =I22*J22 -> 1.2471577
C23: 1b-4 | F23: =F$6 -> 0.15133278 | G23: =Definitions!G$18 -> 0.14734469 | I23: =SUM(F23+G23+H23) -> 0.29867748 | J23: =_xlfn.NORM.INV(RAND(),4,2) -> 3.9622902 | K23: =I23*J23 -> 1.1834468
C24: 1b-5 | F24: =F$6 -> 0.15133278 | G24: =Definitions!G$19 -> 0.0057555668 | I24: =SUM(F24+G24+H24) -> 0.15708835 | J24: =_xlfn.NORM.INV(RAND(),4,2) -> 2.4029307 | K24: =I24*J24 -> 0.37747242
C25: 1b-6 | F25: =F$6 -> 0.15133278 | G25: =Definitions!G$20 -> 0.039061921 | I25: =SUM(F25+G25+H25) -> 0.1903947 | J25: =_xlfn.NORM.INV(RAND(),4,2) -> 5.8736362 | K25: =I25*J25 -> 1.1183092
B26: 1a-2 | C26: 1b-0 | F26: =F$7 -> 0.022901611 | I26: =IF(1-(SUM(I27:I32))<0,0,1-(SUM(I27:I32))) -> 0.50052495 | J26: =_xlfn.NORM.INV(RAND(),4,2) -> 5.3671469 | K26: =I26*J26 -> 2.6863909
C27: 1b-1 | F27: =F$7 -> 0.022901611 | G27: =Definitions!G$15 -> 0.14734469 | I27: =SUM(F27+G27+H27) -> 0.1702463 | J27: =_xlfn.NORM.INV(RAND(),4,2) -> 7.3638205 | K27: =I27*J27 -> 1.2536632
C28: 1b-2 | F28: =F$7 -> 0.022901611 | G28: =Definitions!G$16 -> 0.021710458 | I28: =SUM(F28+G28+H28) -> 0.04461207 | J28: =_xlfn.NORM.INV(RAND(),4,2) -> 4.8285959 | K28: =I28*J28 -> 0.21541366
C29: 1b-3 | F29: =F$7 -> 0.022901611 | G29: =Definitions!G$17 -> 0.00084805222 | I29: =SUM(F29+G29+H29) -> 0.023749663 | J29: =_xlfn.NORM.INV(RAND(),4,2) -> -1.5767755 | K29: =I29*J29 -> -0.037447887
C30: 1b-4 | F30: =F$7 -> 0.022901611 | G30: =Definitions!G$18 -> 0.14734469 | I30: =SUM(F30+G30+H30) -> 0.1702463 | J30: =_xlfn.NORM.INV(RAND(),4,2) -> 5.5082118 | K30: =I30*J30 -> 0.9377527
C31: 1b-5 | F31: =F$7 -> 0.022901611 | G31: =Definitions!G$19 -> 0.0057555668 | I31: =SUM(F31+G31+H31) -> 0.028657178 | J31: =_xlfn.NORM.INV(RAND(),4,2) -> 4.5027684 | K31: =I31*J31 -> 0.12903664
C32: 1b-6 | F32: =F$7 -> 0.022901611 | G32: =Definitions!G$20 -> 0.039061921 | I32: =SUM(F32+G32+H32) -> 0.061963533 | J32: =_xlfn.NORM.INV(RAND(),4,2) -> 3.8478943 | K32: =I32*J32 -> 0.23842912
B33: 1a-3 | C33: 1b-0 | F33: =F$8 -> 0.00023363338 | I33: =IF(1-(SUM(I34:I39))<0,0,1-(SUM(I34:I39))) -> 0.63653282 | J33: =_xlfn.NORM.INV(RAND(),4,2) -> 4.7835679 | K33: =I33*J33 -> 3.0448979
C34: 1b-1 | F34: =F$8 -> 0.00023363338 | G34: =Definitions!G$15 -> 0.14734469 | I34: =SUM(F34+G34+H34) -> 0.14757833 | J34: =_xlfn.NORM.INV(RAND(),4,2) -> 3.5376165 | K34: =I34*J34 -> 0.52207552
C35: 1b-2 | F35: =F$8 -> 0.00023363338 | G35: =Definitions!G$16 -> 0.021710458 | I35: =SUM(F35+G35+H35) -> 0.021944092 | J35: =_xlfn.NORM.INV(RAND(),4,2) -> 4.2022633 | K35: =I35*J35 -> 0.092214852
C36: 1b-3 | F36: =F$8 -> 0.00023363338 | G36: =Definitions!G$17 -> 0.00084805222 | I36: =SUM(F36+G36+H36) -> 0.0010816856 | J36: =_xlfn.NORM.INV(RAND(),4,2) -> 2.3054907 | K36: =I36*J36 -> 0.0024938161
C37: 1b-4 | F37: =F$8 -> 0.00023363338 | G37: =Definitions!G$18 -> 0.14734469 | I37: =SUM(F37+G37+H37) -> 0.14757833 | J37: =_xlfn.NORM.INV(RAND(),4,2) -> 3.5959105 | K37: =I37*J37 -> 0.53067845
C38: 1b-5 | F38: =F$8 -> 0.00023363338 | G38: =Definitions!G$19 -> 0.0057555668 | I38: =SUM(F38+G38+H38) -> 0.0059892002 | J38: =_xlfn.NORM.INV(RAND(),4,2) -> 4.0067575 | K38: =I38*J38 -> 0.023997273
C39: 1b-6 | F39: =F$8 -> 0.00023363338 | G39: =Definitions!G$20 -> 0.039061921 | I39: =SUM(F39+G39+H39) -> 0.039295555 | J39: =_xlfn.NORM.INV(RAND(),4,2) -> 3.8982619 | K39: =I39*J39 -> 0.15318436
B40: 1a-4 | C40: 1b-0 | F40: =F$9 -> 0.15133278 | I40: =IF(1-(SUM(I41:I46))<0,0,1-(SUM(I41:I46))) -> 0 | J40: =_xlfn.NORM.INV(RAND(),4,2) -> 4.5963015 | K40: =I40*J40 -> 0
...
